<?xml version="1.0" ?>
<sdf version="1.8">
	 <model name='inverted_pendulum' canonical_link='staticbase'>
                <pose relative_to='world'>0 0 0 0 0 0</pose>
                <link name='staticbase'>
                        <static>true</static>
                        <pose relative_to='__model__'>0 0 0.015 0 0 0</pose>
                        <inertial>
                                <mass>10</mass>
                                <inertia>
                                        <ixx>0.00035</ixx>
                                        <ixy>0</ixy>
                                        <ixz>0</ixz>
                                        <iyy>0.00035</iyy>
                     			<inertia>
					<ixx>0.00035</ixx>
					<ixy>0</ixy>
					<ixz>0</ixz>
					<iyy>0.00035</iyy>
					<iyz>0</iyz>
					<izz>0.000625</izz>
				</inertia>
			</inertial>
			<visual name='visual'>
				<geometry>
					<cylinder>
						<radius>0.2</radius>
						<length>0.03</length>
					</cylinder>
				</geometry>
				<material>
					<ambient>1.0 1.0 1.0 0.5</ambient>
					<diffuse>1.0 1.0 1.0 0.5</diffuse>
					<specular>1.0 1.0 1.0 0.5</specular>
				</material>
			</visual>
			<collision name='collision'>
				<geometry>
					<cylinder>
						<radius>0.2</radius>
						<length>0.03</length>
					</cylinder>
				</geometry>
			</collision>
		</link>

		<link name='base'>
			<pose relative_to='staticbase'>0 0 0.065 0 0 0</pose>
			<inertial>
				<mass>0.5</mass>
				<inertia>
					<ixx>0.00541666</ixx>
					<ixy>0</ixy>
					<ixz>0</ixz>
					<iyy>0.00541666</iyy>
					<iyz>0</iyz>
					<izz>0.01</izz>
				</inertia>
			</inertial>
			<visual name='visual'>
				<geometry>
					<cylinder>
						<radius>0.2</radius>
						<length>0.1</length>
					</cylinder>
				</geometry>
				<material>
					<ambient>1.0 1.0 1.0 0.5</ambient>
					<diffuse>1.0 1.0 1.0 1</diffuse>
					<specular>1.0 1.0 1.0 1</specular>
				</material>
			</visual>
			<collision name='collision'>
				<geometry>
					<cylinder>
						<radius>0.2</radius>
						<length>0.1</length>
					</cylinder>
				</geometry>
			</collision>
		</link>
		<link name='rod1'>
		<pose relative_to='base'>0.21 0 0.09 0 0 0</pose>
			<inertial>
				<mass>0.1</mass>
				<inertia>
					<ixx>0.000055833</ixx>
					<ixy>0</ixy>
					<ixz>0</ixz>
					<iyy>0.000055833</iyy>
					<iyz>0</iyz>
					<izz>0.000005</izz>
				</inertia>
			</inertial>
			<visual name='visual'>
				<geometry>
					<cylinder>
						<radius>0.01</radius>
						<length>0.08</length>
					</cylinder>
				</geometry>
				<material>
					<ambient>1.0 0.0 0.0 1</ambient>
					<diffuse>1.0 0.0 0.0 1</diffuse>
					<specular>1.0 0.0 0.0 1</specular>
				</material>
			</visual>
			<collision name='collision'>
				<geometry>
					<cylinder>
						<radius>0.05</radius>
						<length>0.03</length>
					</cylinder>
				</geometry>
			</collision>
		</link>

		<link name='mass1'>
		<pose relative_to='rod1'>0 0 0.04 0 0 0</pose>
			<inertial>
				<mass>0.1</mass>
				<inertia>
					<ixx>0.000016</ixx>
					<ixy>0</ixy>
					<ixz>0</ixz>
					<iyy>0.000016</iyy>
					<iyz>0</iyz>
					<izz>0.000016</izz>
				</inertia>
			</inertial>
			<visual name='visual'>
				<geometry>
					<sphere>
						<radius>0.02</radius>
					</sphere>
				</geometry>
				<material>
					<ambient>1.0 0.0 0.0 1</ambient>
					<diffuse>1.0 0.0 0.0 1</diffuse>
					<specular>1.0 0.0 0.0 1</specular>
				</material>
			</visual>
			<collision name='collision'>
				<geometry>
					<sphere>
						<radius>0.02</radius>
					</sphere>
				</geometry>
			</collision>
		</link>
		<joint name='base joint' type='revolute'>
			<pose relative_to='base'/>
			<parent>staticbase</parent>
			<child>base</child>
			<axis>
				<xyz expressed_in='__model__'>0 0 1</xyz>
				<limit>
					<lower>-1.79769e+308</lower>
					<upper>1.79769e+308</upper>
				</limit>
			</axis>
		</joint>
		<joint name='rod joint' type='revolute'>
			<pose relative_to='rod1'>0 0 -0.04 0 0 0</pose>
			<parent>base</parent>
			<child>rod1</child>
			<axis>
				<xyz expressed_in='__model__'>1 0 0</xyz>
				<limit>
					<lower>-1.79769e+308</lower>
					<upper>1.79769e+308</upper>
				</limit>
			</axis>
		</joint>
		<joint name='mass joint' type='fixed'>
			<pose relative_to='mass1'/>
			<parent>rod1</parent>
			<child>mass1</child>
		</joint>

	</model>
</sdf>
